<robot
  name="hustdoublearm">
  <link name="world"/>
  <joint name="fixed" type="fixed">
    <parent link="world"/>
    <child link="base_link"/> 
  </joint>
  <link
    name="base_link">
    <inertial>
      <origin
        xyz="0 0 0.63203"
        rpy="0 0 0" />
      <mass
        value="20.813" />
      <inertia
        ixx="2.7544"
        ixy="0"
        ixz="0"
        iyy="2.7597"
        iyz="0"
        izz="0.061219" />
    </inertial>
    <visual>
      <origin
        xyz="0 0 0"
        rpy="0 0 0" />
      <geometry>
        <mesh
          filename="package://hustdoublearm/meshes/base_link.STL" />
      </geometry>
      <material
        name="">
        <color
          rgba="1 1 1 1" />
      </material>
    </visual>
    <collision>
      <origin
        xyz="0 0 0"
        rpy="0 0 0" />
      <geometry>
        <mesh
          filename="package://hustdoublearm/meshes/base_link.STL" />
      </geometry>
    </collision>
  </link>
  <link
    name="right_link1">
    <inertial>
      <origin
        xyz="0.0042186 0 0.00084454"
        rpy="0 0 0" />
      <mass
        value="0.68868" />
      <inertia
        ixx="0.00048923"
        ixy="0"
        ixz="0"
        iyy="0"
        iyz="0"
        izz="0.00038496" />
    </inertial>
    <visual>
      <origin
        xyz="0 0 0"
        rpy="0 0 0" />
      <geometry>
        <mesh
          filename="package://hustdoublearm/meshes/right_link1.STL" />
      </geometry>
      <material
        name="">
        <color
          rgba="0.89804 0.91765 0.92941 1" />
      </material>
    </visual>
    <collision>
      <origin
        xyz="0 0 0"
        rpy="0 0 0" />
      <geometry>
        <mesh
          filename="package://hustdoublearm/meshes/right_link1.STL" />
      </geometry>
    </collision>
  </link>
  <joint
    name="right_joint1"
    type="revolute">
    <origin
      xyz="-0.184 0 1.155"
      rpy="1.5708 -0.0011298 -1.5708" />
    <parent
      link="base_link" />
    <child
      link="right_link1" />
    <axis
      xyz="0 0 -1" />
    <limit 
    lower="-3.14"       
    upper="3.14"
    effort="1000"
    velocity="100" />
  </joint>
  <link
    name="right_link2">
    <inertial>
      <origin
        xyz="0.0042186 0 0.00084454"
        rpy="0 0 0" />
      <mass
        value="0.68868" />
      <inertia
        ixx="0.00048923"
        ixy="0"
        ixz="0"
        iyy="0"
        iyz="0"
        izz="0.00038496" />
    </inertial>
    <visual>
      <origin
        xyz="0 0 0"
        rpy="0 0 0" />
      <geometry>
        <mesh
          filename="package://hustdoublearm/meshes/right_link2.STL" />
      </geometry>
      <material
        name="">
        <color
          rgba="0.89804 0.91765 0.92941 1" />
      </material>
    </visual>
    <collision>
      <origin
        xyz="0 0 0"
        rpy="0 0 0" />
      <geometry>
        <mesh
          filename="package://hustdoublearm/meshes/right_link2.STL" />
      </geometry>
    </collision>
  </link>
  <joint
    name="right_joint2"
    type="revolute">
    <origin
      xyz="0.08 0 0"
      rpy="-1.5708 0.00082791 -1.5708" />
    <parent
      link="right_link1" />
    <child
      link="right_link2" />
    <axis
      xyz="0 0 -1" />
    <limit 
    lower="-3.14"       
    upper="3.14"
    effort="1000"
  velocity="100" />
  </joint>
  <link
    name="right_link3">
    <inertial>
      <origin
        xyz="0.0024759 0 -0.14834"
        rpy="0 0 0" />
      <mass
        value="3.131" />
      <inertia
        ixx="0.033509"
        ixy="0"
        ixz="0.0010795"
        iyy="0.033898"
        iyz="0"
        izz="0.0022582" />
    </inertial>
    <visual>
      <origin
        xyz="0 0 0"
        rpy="0 0 0" />
      <geometry>
        <mesh
          filename="package://hustdoublearm/meshes/right_link3.STL" />
      </geometry>
      <material
        name="">
        <color
          rgba="0.89804 0.91765 0.92941 1" />
      </material>
    </visual>
    <collision>
      <origin
        xyz="0 0 0"
        rpy="0 0 0" />
      <geometry>
        <mesh
          filename="package://hustdoublearm/meshes/right_link3.STL" />
      </geometry>
    </collision>
  </link>
  <joint
    name="right_joint3"
    type="revolute">
    <origin
      xyz="0.35 0 0"
      rpy="-1.5708 -1.4847 -1.5708" />
    <parent
      link="right_link2" />
    <child
      link="right_link3" />
    <axis
      xyz="0 0 -1" />
    <limit 
    lower="-3.14"       
    upper="3.14"
    effort="1000"
    velocity="100" />
  </joint>
  <link
    name="right_link4">
    <inertial>
      <origin
        xyz="-0.0012304 0 -0.0035566"
        rpy="0 0 0" />
      <mass
        value="0.41012" />
      <inertia
        ixx="0.00016028"
        ixy="0"
        ixz="0"
        iyy="0"
        iyz="0"
        izz="0.00021033" />
    </inertial>
    <visual>
      <origin
        xyz="0 0 0"
        rpy="0 0 0" />
      <geometry>
        <mesh
          filename="package://hustdoublearm/meshes/right_link4.STL" />
      </geometry>
      <material
        name="">
        <color
          rgba="0.89804 0.91765 0.92941 1" />
      </material>
    </visual>
    <collision>
      <origin
        xyz="0 0 0"
        rpy="0 0 0" />
      <geometry>
        <mesh
          filename="package://hustdoublearm/meshes/right_link4.STL" />
      </geometry>
    </collision>
  </link>
  <joint
    name="right_joint4"
    type="revolute">
    <origin
      xyz="0.075 0 0"
      rpy="1.5708 -1.5567 1.5708" />
    <parent
      link="right_link3" />
    <child
      link="right_link4" />
    <axis
      xyz="0 0 -1" />
    <limit 
    lower="-3.14"       
    upper="3.14"
    effort="1000"
    velocity="100" />
  </joint>
  <link
    name="right_link5">
    <inertial>
      <origin
        xyz="-0.00017625 0 -0.16373"
        rpy="0 0 0" />
      <mass
        value="1.2638" />
      <inertia
        ixx="0.012836"
        ixy="0"
        ixz="0"
        iyy="0"
        iyz="0"
        izz="0.00058313" />
    </inertial>
    <visual>
      <origin
        xyz="0 0 0"
        rpy="0 0 0" />
      <geometry>
        <mesh
          filename="package://hustdoublearm/meshes/right_link5.STL" />
      </geometry>
      <material
        name="">
        <color
          rgba="0.89804 0.91765 0.92941 1" />
      </material>
    </visual>
    <collision>
      <origin
        xyz="0 0 0"
        rpy="0 0 0" />
      <geometry>
        <mesh
          filename="package://hustdoublearm/meshes/right_link5.STL" />
      </geometry>
    </collision>
  </link>
  <joint
    name="right_joint5"
    type="revolute">
    <origin
      xyz="0.35 0 0"
      rpy="1.5708 -1.5342 1.5708" />
    <parent
      link="right_link4" />
    <child
      link="right_link5" />
    <axis
      xyz="0 0 -1" />
    <limit 
    lower="-3.14"       
    upper="3.14"
    effort="1000"
    velocity="100" />
  </joint>
  <link
    name="right_link6">
    <inertial>
      <origin
        xyz="-0.00097738 0 -0.0033271"
        rpy="0 0 0" />
      <mass
        value="0.2279" />
      <inertia
        ixx="0.000059519"
        ixy="0"
        ixz="0"
        iyy="0"
        iyz="0"
        izz="0.000081241" />
    </inertial>
    <visual>
      <origin
        xyz="0 0 0"
        rpy="0 0 0" />
      <geometry>
        <mesh
          filename="package://hustdoublearm/meshes/right_link6.STL" />
      </geometry>
      <material
        name="">
        <color
          rgba="0.89804 0.91765 0.92941 1" />
      </material>
    </visual>
    <collision>
      <origin
        xyz="0 0 0"
        rpy="0 0 0" />
      <geometry>
        <mesh
          filename="package://hustdoublearm/meshes/right_link6.STL" />
      </geometry>
    </collision>
  </link>
  <joint
    name="right_joint6"
    type="revolute">
    <origin
      xyz="0.06 0 0"
      rpy="1.5708 -1.5707 1.5708" />
    <parent
      link="right_link5" />
    <child
      link="right_link6" />
    <axis
      xyz="0 0 -1" />
    <limit 
    lower="-3.14"       
    upper="3.14"
    effort="1000"
    velocity="100" />
  </joint>
  <link
    name="right_link7">
    <inertial>
      <origin
        xyz="0 0.0023807 0.093766"
        rpy="0 0 0" />
      <mass
        value="0.56698" />
      <inertia
        ixx="0.0018193"
        ixy="0"
        ixz="0"
        iyy="0"
        iyz="0"
        izz="0.00038792" />
    </inertial>
    <visual>
      <origin
        xyz="0 0 0"
        rpy="0 0 0" />
      <geometry>
        <mesh
          filename="package://hustdoublearm/meshes/right_link7.STL" />
      </geometry>
      <material
        name="">
        <color
          rgba="1 1 1 1" />
      </material>
    </visual>
    <collision>
      <origin
        xyz="0 0 0"
        rpy="0 0 0" />
      <geometry>
        <mesh
          filename="package://hustdoublearm/meshes/right_link7.STL" />
      </geometry>
    </collision>
  </link>
  <joint
    name="right_joint7"
    type="revolute">
    <origin
      xyz="0.03 0 0"
      rpy="1.5708 -1.4552 1.5708" />
    <parent
      link="right_link6" />
    <child
      link="right_link7" />
    <axis
      xyz="0 0 1" />
    <limit 
    lower="-3.14"       
    upper="3.14"
    effort="1000"
    velocity="100" />
  </joint>

  <link
    name="left_link1">
    <inertial>
      <origin
        xyz="0.0042186 0 0.00084454"
        rpy="0 0 0" />
      <mass
        value="0.68868" />
      <inertia
        ixx="0.00048923"
        ixy="0"
        ixz="0"
        iyy="0"
        iyz="0"
        izz="0.00038496" />
    </inertial>
    <visual>
      <origin
        xyz="0 0 0"
        rpy="0 0 0" />
      <geometry>
        <mesh
          filename="package://hustdoublearm/meshes/left_link1.STL" />
      </geometry>
      <material
        name="">
        <color
          rgba="0.89804 0.91765 0.92941 1" />
      </material>
    </visual>
    <collision>
      <origin
        xyz="0 0 0"
        rpy="0 0 0" />
      <geometry>
        <mesh
          filename="package://hustdoublearm/meshes/left_link1.STL" />
      </geometry>
    </collision>
  </link>
  <joint
    name="left_joint1"
    type="revolute">
    <origin
      xyz="0.184 0 1.155"
      rpy="-1.5708 -0.0015412 -1.5708" />
    <parent
      link="base_link" />
    <child
      link="left_link1" />
    <axis
      xyz="0 0 -1" />
    <limit 
    lower="-3.14"       
    upper="3.14"
    effort="1000"
    velocity="100" />
  </joint>
  <link
    name="left_link2">
    <inertial>
      <origin
        xyz="0.0042186 0 0.00084454"
        rpy="0 0 0" />
      <mass
        value="0.68868" />
      <inertia
        ixx="0.00048923"
        ixy="0"
        ixz="0"
        iyy="0"
        iyz="0"
        izz="0.00038496" />
    </inertial>
    <visual>
      <origin
        xyz="0 0 0"
        rpy="0 0 0" />
      <geometry>
        <mesh
          filename="package://hustdoublearm/meshes/left_link2.STL" />
      </geometry>
      <material
        name="">
        <color
          rgba="0.89804 0.91765 0.92941 1" />
      </material>
    </visual>
    <collision>
      <origin
        xyz="0 0 0"
        rpy="0 0 0" />
      <geometry>
        <mesh
          filename="package://hustdoublearm/meshes/left_link2.STL" />
      </geometry>
    </collision>
  </link>
  <joint
    name="left_joint2"
    type="revolute">
    <origin
      xyz="0.08 0 0"
      rpy="1.5708 0.016458 1.5708" />
    <parent
      link="left_link1" />
    <child
      link="left_link2" />
    <axis
      xyz="0 0 -1" />
    <limit 
    lower="-3.14"       
    upper="3.14"
    effort="1000"
    velocity="100" />
  </joint>
  <link
    name="left_link3">
    <inertial>
      <origin
        xyz="0.0024641 0.00025279 -0.14054"
        rpy="0 0 0" />
      <mass
        value="3.131" />
      <inertia
        ixx="0.03158"
        ixy="0"
        ixz="0.0010523"
        iyy="0.031965"
        iyz="0"
        izz="0.0022582" />
    </inertial>
    <visual>
      <origin
        xyz="0 0 0"
        rpy="0 0 0" />
      <geometry>
        <mesh
          filename="package://hustdoublearm/meshes/left_link3.STL" />
      </geometry>
      <material
        name="">
        <color
          rgba="0.89804 0.91765 0.92941 1" />
      </material>
    </visual>
    <collision>
      <origin
        xyz="0 0 0"
        rpy="0 0 0" />
      <geometry>
        <mesh
          filename="package://hustdoublearm/meshes/left_link3.STL" />
      </geometry>
    </collision>
  </link>
  <joint
    name="left_joint3"
    type="revolute">
    <origin
      xyz="0.35 0 0"
      rpy="1.5708 -1.4847 1.5708" />
    <parent
      link="left_link2" />
    <child
      link="left_link3" />
    <axis
      xyz="0 0 -1" />
    <limit 
    lower="-3.14"       
    upper="3.14"
    effort="1000"
    velocity="100" />
  </joint>
  <link
    name="left_link4">
    <inertial>
      <origin
        xyz="-0.0012304 0 -0.0035566"
        rpy="0 0 0" />
      <mass
        value="0.41012" />
      <inertia
        ixx="0.00016028"
        ixy="0"
        ixz="0"
        iyy="0"
        iyz="0"
        izz="0.00021033" />
    </inertial>
    <visual>
      <origin
        xyz="0 0 0"
        rpy="0 0 0" />
      <geometry>
        <mesh
          filename="package://hustdoublearm/meshes/left_link4.STL" />
      </geometry>
      <material
        name="">
        <color
          rgba="0.89804 0.91765 0.92941 1" />
      </material>
    </visual>
    <collision>
      <origin
        xyz="0 0 0"
        rpy="0 0 0" />
      <geometry>
        <mesh
          filename="package://hustdoublearm/meshes/left_link4.STL" />
      </geometry>
    </collision>
  </link>
  <joint
    name="left_joint4"
    type="revolute">
    <origin
      xyz="0.075 0 0"
      rpy="-1.5708 -1.5567 -1.5708" />
    <parent
      link="left_link3" />
    <child
      link="left_link4" />
    <axis
      xyz="0 0 -1" />
    <limit 
    lower="-3.14"       
    upper="3.14"
    effort="1000"
    velocity="100" />
  </joint>
  <link
    name="left_link5">
    <inertial>
      <origin
        xyz="-0.00017625 0 -0.16373"
        rpy="0 0 0" />
      <mass
        value="1.2638" />
      <inertia
        ixx="0.012836"
        ixy="0"
        ixz="0"
        iyy="0"
        iyz="0"
        izz="0.00058313" />
    </inertial>
    <visual>
      <origin
        xyz="0 0 0"
        rpy="0 0 0" />
      <geometry>
        <mesh
          filename="package://hustdoublearm/meshes/left_link5.STL" />
      </geometry>
      <material
        name="">
        <color
          rgba="0.89804 0.91765 0.92941 1" />
      </material>
    </visual>
    <collision>
      <origin
        xyz="0 0 0"
        rpy="0 0 0" />
      <geometry>
        <mesh
          filename="package://hustdoublearm/meshes/left_link5.STL" />
      </geometry>
    </collision>
  </link>
  <joint
    name="left_joint5"
    type="revolute">
    <origin
      xyz="0.35 0 0"
      rpy="-1.5708 -1.3914 -1.5708" />
    <parent
      link="left_link4" />
    <child
      link="left_link5" />
    <axis
      xyz="0 0 -1" />
    <limit 
    lower="-3.14"       
    upper="3.14"
    effort="1000"
    velocity="100" />
  </joint>
  <link
    name="left_link6">
    <inertial>
      <origin
        xyz="-0.00097738 0 -0.0033271"
        rpy="0 0 0" />
      <mass
        value="0.2279" />
      <inertia
        ixx="0.000059519"
        ixy="0"
        ixz="0"
        iyy="0"
        iyz="0"
        izz="0.000081241" />
    </inertial>
    <visual>
      <origin
        xyz="0 0 0"
        rpy="0 0 0" />
      <geometry>
        <mesh
          filename="package://hustdoublearm/meshes/left_link6.STL" />
      </geometry>
      <material
        name="">
        <color
          rgba="0.89804 0.91765 0.92941 1" />
      </material>
    </visual>
    <collision>
      <origin
        xyz="0 0 0"
        rpy="0 0 0" />
      <geometry>
        <mesh
          filename="package://hustdoublearm/meshes/left_link6.STL" />
      </geometry>
    </collision>
  </link>
  <joint
    name="left_joint6"
    type="revolute">
    <origin
      xyz="0.06 0 0"
      rpy="-0.83867 -1.5708 -2.3029" />
    <parent
      link="left_link5" />
    <child
      link="left_link6" />
    <axis
      xyz="0 0 -1" />
    <limit 
    lower="-3.14"      
     upper="3.14"
    effort="1000"
    velocity="100" />
  </joint>
  <link
    name="left_link7">
    <inertial>
      <origin
        xyz="-0.0023807 0 0.093766"
        rpy="0 0 0" />
      <mass
        value="0.56698" />
      <inertia
        ixx="0.0015848"
        ixy="0"
        ixz="0"
        iyy="0"
        iyz="0"
        izz="0.00038792" />
    </inertial>
    <visual>
      <origin
        xyz="0 0 0"
        rpy="0 0 0" />
      <geometry>
        <mesh
          filename="package://hustdoublearm/meshes/left_link7.STL" />
      </geometry>
      <material
        name="">
        <color
          rgba="1 1 1 1" />
      </material>
    </visual>
    <collision>
      <origin
        xyz="0 0 0"
        rpy="0 0 0" />
      <geometry>
        <mesh
          filename="package://hustdoublearm/meshes/left_link7.STL" />
      </geometry>
    </collision>
  </link>
  <joint
    name="left_joint7"
    type="revolute">
    <origin
      xyz="0.03 0 0"
      rpy="-1.5708 0 -1.5708" />
    <parent
      link="left_link6" />
    <child
      link="left_link7" />
    <axis
      xyz="0 0 1" />
    <limit 
    lower="-3.14"       
    upper="3.14"
    effort="1000"
    velocity="100" />
  </joint>

  <transmission name="left_tran1">
    <type>transmission_interface/SimpleTransmission</type>
    <joint name="left_joint1">
      <hardwareInterface>hardware_interface/VelocityJointInterface</hardwareInterface>
    </joint>
    <actuator name="left_motor1">
      <hardwareInterface>hardware_interface/VelocityJointInterface</hardwareInterface>
      <mechanicalReduction>1</mechanicalReduction>
    </actuator>
  </transmission>
  <transmission name="left_tran2">
    <type>transmission_interface/SimpleTransmission</type>
    <joint name="left_joint2">
      <hardwareInterface>hardware_interface/VelocityJointInterface</hardwareInterface>
    </joint>
    <actuator name="left_motor2">
      <hardwareInterface>hardware_interface/VelocityJointInterface</hardwareInterface>
      <mechanicalReduction>1</mechanicalReduction>
    </actuator>
  </transmission>
  <transmission name="left_tran3">
    <type>transmission_interface/SimpleTransmission</type>
    <joint name="left_joint3">
      <hardwareInterface>hardware_interface/VelocityJointInterface</hardwareInterface>
    </joint>
    <actuator name="left_motor3">
      <hardwareInterface>hardware_interface/VelocityJointInterface</hardwareInterface>
      <mechanicalReduction>1</mechanicalReduction>
    </actuator>
  </transmission>
  <transmission name="left_tran4">
    <type>transmission_interface/SimpleTransmission</type>
    <joint name="left_joint4">
      <hardwareInterface>hardware_interface/VelocityJointInterface</hardwareInterface>
    </joint>
    <actuator name="left_motor4">
      <hardwareInterface>hardware_interface/VelocityJointInterface</hardwareInterface>
      <mechanicalReduction>1</mechanicalReduction>
    </actuator>
  </transmission>
  <transmission name="left_tran5">
    <type>transmission_interface/SimpleTransmission</type>
    <joint name="left_joint5">
      <hardwareInterface>hardware_interface/VelocityJointInterface</hardwareInterface>
    </joint>
    <actuator name="left_motor5">
      <hardwareInterface>hardware_interface/VelocityJointInterface</hardwareInterface>
      <mechanicalReduction>1</mechanicalReduction>
    </actuator>
  </transmission>
  <transmission name="left_tran6">
    <type>transmission_interface/SimpleTransmission</type>
    <joint name="left_joint6">
      <hardwareInterface>hardware_interface/VelocityJointInterface</hardwareInterface>
    </joint>
    <actuator name="left_motor6">
      <hardwareInterface>hardware_interface/VelocityJointInterface</hardwareInterface>
      <mechanicalReduction>1</mechanicalReduction>
    </actuator>
  </transmission>
  <transmission name="left_tran7">
    <type>transmission_interface/SimpleTransmission</type>
    <joint name="left_joint7">
      <hardwareInterface>hardware_interface/VelocityJointInterface</hardwareInterface>
    </joint>
    <actuator name="left_motor7">
      <hardwareInterface>hardware_interface/VelocityJointInterface</hardwareInterface>
      <mechanicalReduction>1</mechanicalReduction>
    </actuator>
  </transmission>

  <transmission name="right_tran1">
    <type>transmission_interface/SimpleTransmission</type>
    <joint name="right_joint1">
      <hardwareInterface>hardware_interface/VelocityJointInterface</hardwareInterface>
    </joint>
    <actuator name="right_motor1">
      <hardwareInterface>hardware_interface/VelocityJointInterface</hardwareInterface>
      <mechanicalReduction>1</mechanicalReduction>
    </actuator>
  </transmission>
  <transmission name="right_tran2">
    <type>transmission_interface/SimpleTransmission</type>
    <joint name="right_joint2">
      <hardwareInterface>hardware_interface/VelocityJointInterface</hardwareInterface>
    </joint>
    <actuator name="right_motor2">
      <hardwareInterface>hardware_interface/VelocityJointInterface</hardwareInterface>
      <mechanicalReduction>1</mechanicalReduction>
    </actuator>
  </transmission>
  <transmission name="right_tran3">
    <type>transmission_interface/SimpleTransmission</type>
    <joint name="right_joint3">
      <hardwareInterface>hardware_interface/VelocityJointInterface</hardwareInterface>
    </joint>
    <actuator name="right_motor3">
      <hardwareInterface>hardware_interface/VelocityJointInterface</hardwareInterface>
      <mechanicalReduction>1</mechanicalReduction>
    </actuator>
  </transmission>
  <transmission name="right_tran4">
    <type>transmission_interface/SimpleTransmission</type>
    <joint name="right_joint4">
      <hardwareInterface>hardware_interface/VelocityJointInterface</hardwareInterface>
    </joint>
    <actuator name="right_motor4">
      <hardwareInterface>hardware_interface/VelocityJointInterface</hardwareInterface>
      <mechanicalReduction>1</mechanicalReduction>
    </actuator>
  </transmission>
  <transmission name="right_tran5">
    <type>transmission_interface/SimpleTransmission</type>
    <joint name="right_joint5">
      <hardwareInterface>hardware_interface/VelocityJointInterface</hardwareInterface>
    </joint>
    <actuator name="right_motor5">
      <hardwareInterface>hardware_interface/VelocityJointInterface</hardwareInterface>
      <mechanicalReduction>1</mechanicalReduction>
    </actuator>
  </transmission>
  <transmission name="right_tran6">
    <type>transmission_interface/SimpleTransmission</type>
    <joint name="right_joint6">
      <hardwareInterface>hardware_interface/VelocityJointInterface</hardwareInterface>
    </joint>
    <actuator name="right_motor6">
      <hardwareInterface>hardware_interface/VelocityJointInterface</hardwareInterface>
      <mechanicalReduction>1</mechanicalReduction>
    </actuator>
  </transmission>
  <transmission name="right_tran7">
    <type>transmission_interface/SimpleTransmission</type>
    <joint name="right_joint7">
      <hardwareInterface>hardware_interface/VelocityJointInterface</hardwareInterface>
    </joint>
    <actuator name="right_motor7">
      <hardwareInterface>hardware_interface/VelocityJointInterface</hardwareInterface>
      <mechanicalReduction>1</mechanicalReduction>
    </actuator>
  </transmission>
  <gazebo>
    <plugin filename="libgazebo_ros_control.so" name="gazebo_ros_control">
      <robotNamespace>/hustdoublearm</robotNamespace>
      <robotSimType>gazebo_ros_control/DefaultRobotHWSim</robotSimType>
    </plugin>
  </gazebo>
</robot>